Workbook
Name ENTRADA: 'DEZEMBRO-25'!$AN$1:$BR$120
Name FINAL: #REF!
Name SAÍDA: 'DEZEMBRO-25'!$H$1:$AL$111
Name validades: Tabela14[]

Sheet ESTOQUE GERAL
A1: MAIS SAIU NO MÊS | B1: produtos | C1: CLAS. | D1: vencimento | E1: SAÍDA | F1: ESTOQUE | G1: ENTRADA | I1: TOTAL | J1: 1 | K1: 2 | L1: 3 | M1: 4 | N1: 5 | O1: 6 | P1: 7 | Q1: 8 | R1: 9 | S1: 10 | T1: 11 | U1: 12 | V1: 13 | W1: 14 | X1: 15 | Y1: 16 | Z1: 17 | AA1: 18 | AB1: 19 | AC1: 20 | AD1: 21 | AE1: 22 | AF1: 23 | AG1: 24 | AH1: 25 | AI1: 26 | AJ1: 27 | AK1: 28 | AL1: 29 | AM1: 30 | AN1: 31
A2: =-SUM(J2:AN2) -> 120 | B2: CLOREXIDINA degermante 2% | C2: LT | D2: 46327 | E2: 5 | F2: 100 | G2: 0 | I2: =SUM(F2+G2-E2,J2:AN2) -> -25 | M2: -120
A3: =-SUM(J3:AN3) -> 120 | B3: digluconato de clorexidina 0,5% | C3: LT | D3: 46631 | E3: 0 | F3: 35 | I3: =SUM(F3+G3-E3,J3:AN3) -> -85 | M3: -120
A4: =-SUM(J4:AN4) -> 120 | B4: ABAIXADORES P/LÍNGUA | C4: UND | D4: 47178 | F4: 185 | I4: =SUM(F4+G4-E4,J4:AN4) -> 65 | M4: -120
A5: =-SUM(J5:AN5) -> 18 | B5: ADESIVO P/ FIXAÇÃO DE DISPOSITIVOS INTRAVENOSOS | C5: UND | D5: 46113 | F5: 750 | I5: =SUM(F5+G5-E5,J5:AN5) -> 732 | M5: -18
A6: =-SUM(J6:AN6) -> 10 | B6: AGENDA PERMANENTE | C6: NULO | F6: 0 | I6: =SUM(F6+G6-E6,J6:AN6) -> -10 | M6: -10
A7: =-SUM(J7:AN7) -> 10 | B7: AGENDAMENTO DE CONSULTA | C7: UND | F7: 241 | I7: =SUM(F7+G7-E7,J7:AN7) -> 231 | M7: -10
A8: =-SUM(J8:AN8) -> 5 | B8: ÁGUA OXIGENADA | C8: UND | F8: 0 | I8: =SUM(F8+G8-E8,J8:AN8) -> -5 | M8: -5
A9: =-SUM(J9:AN9) -> 4 | B9: ÁGUA P/ INJEÇÃO | C9: UND | D9: 45931 | F9: 45 | I9: =SUM(F9+G9-E9,J9:AN9) -> 41 | M9: -4
A10: =-SUM(J10:AN10) -> 4 | B10: ÁGUA SANITÁRIA 2lt | I10: =SUM(F10+G10-E10,J10:AN10) -> -4 | M10: -4
A11: =-SUM(J11:AN11) -> 4 | B11: ÁGUA SANITÁRIA 1lt | I11: =SUM(F11+G11-E11,J11:AN11) -> -4 | M11: -4
A12: =-SUM(J12:AN12) -> 3 | B12: ÁGUA SANITÁRIA 2L | I12: =SUM(F12+G12-E12,J12:AN12) -> -3 | M12: -3
A13: =-SUM(J13:AN13) -> 3 | B13: AGULHA HIPODÉRMICA25x0,6 C/100 | C13: CX | F13: 173 | I13: =SUM(F13+G13-E13,J13:AN13) -> 170 | M13: -3
A14: =-SUM(J14:AN14) -> 2 | B14: AGULHA HIPODÉRMICA25x7 C/100 | C14: CX | F14: 106 | I14: =SUM(F14+G14-E14,J14:AN14) -> 104 | M14: -2
A15: =-SUM(J15:AN15) -> 2 | B15: AGULHA HIPODÉRMICA25X8 C/100 | C15: CX | F15: 68 | I15: =SUM(F15+G15-E15,J15:AN15) -> 66 | M15: -2
A16: =-SUM(J16:AN16) -> 2 | B16: AGULHA HIPODÉRMICA40X12 C/100 | C16: CX | F16: 71 | I16: =SUM(F16+G16-E16,J16:AN16) -> 69 | M16: -2
A17: =-SUM(J17:AN17) -> 2 | B17: AGULHA HIPODÉRMICA 13x45 C/100 | C17: CX | F17: 137 | I17: =SUM(F17+G17-E17,J17:AN17) -> 135 | M17: -2
A18: =-SUM(J18:AN18) -> 2 | B18: AGULHA HIPODÉRMICA 20X55 C/100 | C18: CX | F18: 49 | I18: =SUM(F18+G18-E18,J18:AN18) -> 47 | M18: -2
A19: =-SUM(J19:AN19) -> 2 | B19: AGULHA P/ GLICOSE (LANCETA) | C19: NULO | F19: 0 | I19: =SUM(F19+G19-E19,J19:AN19) -> -2 | M19: -2
A20: =-SUM(J20:AN20) -> 2 | B20: ÁLCOOL 70% | I20: =SUM(F20+G20-E20,J20:AN20) -> -2 | M20: -2
A21: =-SUM(J21:AN21) -> 2 | B21: ÁLCOOL 99% HOSPITALAR | C21: UND | D21: 46296 | F21: 50 | I21: =SUM(F21+G21-E21,J21:AN21) -> 48 | M21: -2
A22: =-SUM(J22:AN22) -> 1 | B22: ÁLCOOL IODADO (POLVIDINE TÓPICO) | C22: LT | D22: 45839 | F22: 118 | I22: =SUM(F22+G22-E22,J22:AN22) -> 117 | M22: -1
A23: =-SUM(J23:AN23) -> 1 | B23: ÁLCOOOL EM GEL 70% | I23: =SUM(F23+G23-E23,J23:AN23) -> -1 | M23: -1
A24: =-SUM(J24:AN24) -> 0 | B24: ALFINETE COM CABEÇA | C24: CX | F24: 0 | I24: =SUM(F24+G24-E24,J24:AN24) -> 0 | L24: 0 | M24: 0
A25: =-SUM(J25:AN25) -> 0 | B25: ALFINETE COMUM | C25: NULO | F25: 0 | I25: =SUM(F25+G25-E25,J25:AN25) -> 0 | M25: 0
A26: =-SUM(J26:AN26) -> 0 | B26: ALGODÃO HIDROFILO | C26: UND | D26: 47178 | F26: 70 | I26: =SUM(F26+G26-E26,J26:AN26) -> 70 | M26: 0
A27: =-SUM(J27:AN27) -> 0 | B27: ALGODÃO ORTOPEDICO 10CM | C27: NULO | F27: 0 | I27: =SUM(F27+G27-E27,J27:AN27) -> 0 | M27: 0
A28: =-SUM(J28:AN28) -> 0 | B28: ALGODÃO ORTOPEDICO 20CM | C28: NULO | F28: 0 | I28: =SUM(F28+G28-E28,J28:AN28) -> 0 | M28: 0
A29: =-SUM(J29:AN29) -> 0 | B29: ALMOFADA PARA CARIMBO | C29: UND | F29: 39 | I29: =SUM(F29+G29-E29,J29:AN29) -> 39 | M29: 0
A30: =-SUM(J30:AN30) -> 0 | B30: ALMOFADA PARA CARIMBO | C30: UND | F30: 54 | I30: =SUM(F30+G30-E30,J30:AN30) -> 54 | M30: 0
A31: =-SUM(J31:AN31) -> 0 | B31: ALMOTOLIA 250 ML | C31: UND | F31: 0 | I31: =SUM(F31+G31-E31,J31:AN31) -> 0 | M31: 0
A32: =-SUM(J32:AN32) -> 0 | B32: ALMOTOLIA 500 ML | C32: UND | F32: 0 | I32: =SUM(F32+G32-E32,J32:AN32) -> 0 | M32: 0
A33: =-SUM(J33:AN33) -> 0 | B33: AMACIANTE | I33: =SUM(F33+G33-E33,J33:AN33) -> 0 | M33: 0
A34: =-SUM(J34:AN34) -> 0 | B34: Aparelho MEDIDOR GLICOSE (GLICOSÍMETRO) | C34: NULO | F34: 0 | I34: =SUM(F34+G34-E34,J34:AN34) -> 0 | M34: 0
A35: =-SUM(J35:AN35) -> 0 | B35: ARQUIVO | I35: =SUM(F35+G35-E35,J35:AN35) -> 0 | M35: 0
A36: =-SUM(J36:AN36) -> 0 | B36: ATADURA CREPE 10cm | C36: UND | F36: 0 | I36: =SUM(F36+G36-E36,J36:AN36) -> 0 | M36: 0
A37: =-SUM(J37:AN37) -> 0 | B37: ATADURA CREPE 15cm | C37: UND | D37: 47150 | F37: 60 | I37: =SUM(F37+G37-E37,J37:AN37) -> 60 | M37: 0
A38: =-SUM(J38:AN38) -> 0 | B38: ATADURA CREPE 20cm | C38: UND | D38: 47150 | F38: 60 | I38: =SUM(F38+G38-E38,J38:AN38) -> 60 | M38: 0
A39: =-SUM(J39:AN39) -> 0 | B39: ATADURA DE ALGODÃO 10CM | C39: NULO | F39: 0 | I39: =SUM(F39+G39-E39,J39:AN39) -> 0 | M39: 0
A40: =-SUM(J40:AN40) -> 0 | B40: ATADURA DE ALGODÃO 15CM | C40: NULO | F40: 0 | I40: =SUM(F40+G40-E40,J40:AN40) -> 0 | M40: 0
...

Sheet VALIDADE
A1: produtos | B1: vencimento | C1: OBS:
A2: ÁLCOOL IODADO (POLVIDINE TÓPICO) | B2: 45839
A3: ETER ALCOLIZADO 35% | B3: 45870
A4: ÁGUA P/ INJEÇÃO | B4: 45931
A5: CREME PREVENTIVO | B5: 45962
A6: ETER 1LT | B6: 45992
A7: BATERIA CR 2450 | B7: 46023
A8: FITA CREPE ZEBRADA P/ AUTOCLAVE | B8: 46023
A9: gel condutor 1kg | B9: 46023
A10: SONDA URETRALN°18 | B10: 46023
A11: FIXADOR CELULAR | B11: 46054
A12: SULFADIAZINA DE PRATA | B12: 46054
A13: IODOPOLVIDINA DEGERMANTE 1L | B13: 46082
... A39: SONDA DE FOLEY N°12 | B39: 46388
A40: SONDAS NASOGASTRIGAS NUMEROS VARIADOS | B40: 46388 | C40: A VALIDADE REPRESENTA SOMENTE O ANO
A41: TUBO ENDOTRAQUEAL N°4 | B41: 46388
A42: LUVA ESTÉREO N°6 | B42: 46419
A43: MARCA TEXTO VERDE | B43: 46419
A44: BORRACHA | B44: 46447
A45: ÁGUA OXIGENADA | B45: 46569
A46: FITA CIRÚRGICA MICROPOROSA 05CM | B46: 46569
A47: SONDA DE FOLEY N°18 | B47: 46569
A48: TUBO ENDOTRAQUEAL N°8,5 | B48: 46569
A49: VASELINA LÍQUIDA 1L | B49: 46569
A50: SONDA ENDOTRAQUEAL C/ BALÃO N°5 | B50: 46572
A51: BOBINA P/ ESTERILIZAÇÃO 300X100 | B51: 46600
A52: CATEGUTE CROMADO 2 | B52: 46600
... A56: LUVA ESTÉREO N°8,5 | B56: 46722
A57: FIO AGULHA NYLON TAMANHOS VARIADOS | B57: 46753 | C57: A VALIDADE REPRESENTA SOMENTE O ANO
A58: LUVA G | B58: 46753
A59: LUVA PP | B59: 46753
A60: AGULHA HIPODÉRMICA 13x45 C/100 | B60: 46813
A61: CATEGUTE SIMPLES 2 | B61: 46813
A62: CATETER INTRAVENOSO 18 | B62: 46813
A63: LUVA P | B63: 46813
A64: TUBO ENDOTRAQUEAL N°7 | B64: 46813
A65: TUBO ENDOTRAQUEAL N°8 | B65: 46813
A66: CATETER PERIFÉRICO 18 G | B66: 46844
A67: FIO AGULHA NYLON N°0/20 | B67: 46874
A68: TUBO ENDOTRAQUEAL N°6 | B68: 46874
...

Sheet DEZEMBRO-25
A1: DATA DE INÍCIO: | B1: 45963 | C1: DATA FINAL: | D1: 45964 | E1: SOMA | F1: DE | G1: ESTOQUE
A2: Produto | B2: Quantidade | C2: CLAS. | D2: Observação | E2: ENTRADA | F2: SAÍDA | G2: SUBTOTAL | H2: 01/12/2025 | I2: 02/12/2025 | J2: 03/12/2025 | K2: 04/12/2025 | L2: 05/12/2025 | M2: 06/12/2025 | N2: 07/12/2025 | O2: 08/12/2025 | P2: 09/12/2025 | Q2: 10/12/2025 | R2: 11/12/2025 | S2: 12/12/2025 | T2: 13/12/2025 | U2: 14/12/2025 | V2: 15/12/2025 | W2: 16/12/2025 | X2: 17/12/2025 | Y2: 18/12/2025 | Z2: 19/12/2025 | AA2: 20/12/2025 | AB2: 21/12/2025 | AC2: 22/12/2025 | AD2: 23/12/2025 | AE2: 24/12/2025 | AF2: 25/12/2025 | AG2: 26/12/2025 | AH2: 27/12/2025 | AI2: 28/12/2025 | AJ2: 29/12/2025 | AK2: 30/12/2025 | AL2: 31/12/2025 | AM2: SAIDA | AN2: Colunas1 | AO2: Colunas2 | AP2: Colunas3 | AQ2: Colunas4 | AR2: Colunas5 | AS2: Colunas6 | AT2: Colunas7 | AU2: Colunas8 | AV2: Colunas9 | AW2: Colunas10 | AX2: Colunas11 | AY2: Colunas12 | AZ2: Colunas13 | BA2: Colunas14 | BB2: Colunas15 | BC2: Colunas16 | BD2: Colunas17 | BE2: Colunas18 | BF2: Colunas19 | BG2: Colunas20 | BH2: Colunas21 | BI2: Colunas22 | BJ2: Colunas23 | BK2: Colunas24 | BL2: Colunas25 | BM2: Colunas26 | BN2: Colunas27 | BO2: Colunas28 | BP2: Colunas29 | BQ2: Colunas30 | BR2: Colunas31 | BS2: entrada
A3: ÁGUA SANITÁRIA 2L | B3: 64 | C3: CX | D3: C/100UN | G3: =SUM(Tabela1[[#This Row],[Quantidade]]+E3-F3+BS3-AM3) -> 64 | AM3: =SUM('DEZEMBRO-25'!$H3:$AL3) -> 0 | BS3: =SUM(AN3:BR3) -> 0
A4: AGULHA HIPODÉRMICA 13X4.5 C/100 | B4: 60 | C4: CX | D4: C/100UN | G4: =SUM(Tabela1[[#This Row],[Quantidade]]+E4-F4+BS4-AM4) -> 60 | AM4: =SUM('DEZEMBRO-25'!$H4:$AL4) -> 0 | BS4: =SUM(AN4:BR4) -> 0
A5: AGULHA HIPODÉRMICA 20X5.5 C/100 | B5: 60 | C5: CX | D5: C/100UN | G5: =SUM(Tabela1[[#This Row],[Quantidade]]+E5-F5+BS5-AM5) -> 60 | AM5: =SUM('DEZEMBRO-25'!$H5:$AL5) -> 0 | BS5: =SUM(AN5:BR5) -> 0
A6: AGULHA HIPODÉRMICA 25X8 C/100 | B6: 71 | C6: CX | D6: C/100UN | G6: =SUM(Tabela1[[#This Row],[Quantidade]]+E6-F6+BS6-AM6) -> 71 | AM6: =SUM('DEZEMBRO-25'!$H6:$AL6) -> 0 | BS6: =SUM(AN6:BR6) -> 0
A7: AGULHA HIPODÉRMICA 40X12 C/100 | B7: 20 | C7: CX | D7: C/100UN | G7: =SUM(Tabela1[[#This Row],[Quantidade]]+E7-F7+BS7-AM7) -> 20 | AM7: =SUM('DEZEMBRO-25'!$H7:$AL7) -> 0 | BS7: =SUM(AN7:BR7) -> 0
A8: ÁLCOOL | B8: TEM MUITO | C8: TEM MUITO | D8: TEM MUITO | G8: =SUM(Tabela1[[#This Row],[Quantidade]]+E8-F8+BS8-AM8) -> #VALUE! | AM8: =SUM('DEZEMBRO-25'!$H8:$AL8) -> 0 | BS8: =SUM(AN8:BR8) -> 0
A9: ALGODÃO HIDRÓFILO | B9: 125 | C9: UND | D9: 500G | G9: =SUM(Tabela1[[#This Row],[Quantidade]]+E9-F9+BS9-AM9) -> 125 | AM9: =SUM('DEZEMBRO-25'!$H9:$AL9) -> 0 | BS9: =SUM(AN9:BR9) -> 0
A10: ALGODÃO ORTOPÉDICO 10CM | B10: 0 | C10: 0 | D10: 0 | G10: =SUM(Tabela1[[#This Row],[Quantidade]]+E10-F10+BS10-AM10) -> 0 | AM10: =SUM('DEZEMBRO-25'!$H10:$AL10) -> 0 | BS10: =SUM(AN10:BR10) -> 0
A11: ALGODÃO ORTOPÉDICO 20CM | B11: 100 | C11: UND | D11: OLHAR COM ZE MARIA | G11: =SUM(Tabela1[[#This Row],[Quantidade]]+E11-F11+BS11-AM11) -> 100 | AM11: =SUM('DEZEMBRO-25'!$H11:$AL11) -> 0 | BS11: =SUM(AN11:BR11) -> 0
A12: ALMOTOLIA 250 ML | B12: 100 | C12: UND | D12: NÃO SAI | G12: =SUM(Tabela1[[#This Row],[Quantidade]]+E12-F12+BS12-AM12) -> 100 | AM12: =SUM('DEZEMBRO-25'!$H12:$AL12) -> 0 | BS12: =SUM(AN12:BR12) -> 0
A13: ALMOTOLIA 500 ML | B13: 0 | C13: 0 | D13: 0 | G13: =SUM(Tabela1[[#This Row],[Quantidade]]+E13-F13+BS13-AM13) -> 0 | AM13: =SUM('DEZEMBRO-25'!$H13:$AL13) -> 0 | BS13: =SUM(AN13:BR13) -> 0
A14: APARELHO MEDIDOR GLICOSE (GLICOSÍMETRO) | B14: CONTAR | C14: CONTAR | D14: CONTAR | G14: =SUM(Tabela1[[#This Row],[Quantidade]]+E14-F14+BS14-AM14) -> #VALUE! | AM14: =SUM('DEZEMBRO-25'!$H14:$AL14) -> 0 | BS14: =SUM(AN14:BR14) -> 0
A15: ATADURA CREPE 10CM | B15: 90 | C15: PCT | D15: SAI MUITO | G15: =SUM(Tabela1[[#This Row],[Quantidade]]+E15-F15+BS15-AM15) -> 90 | AM15: =SUM('DEZEMBRO-25'!$H15:$AL15) -> 0 | BS15: =SUM(AN15:BR15) -> 0
A16: ATADURA CREPE 15CM | B16: 69 | C16: PCT | D16: SAI MUITO | G16: =SUM(Tabela1[[#This Row],[Quantidade]]+E16-F16+BS16-AM16) -> 69 | AM16: =SUM('DEZEMBRO-25'!$H16:$AL16) -> 0 | BS16: =SUM(AN16:BR16) -> 0
A17: ATADURA CREPE 20CM | B17: 34 | C17: PCT | D17: SAI MUITO | G17: =SUM(Tabela1[[#This Row],[Quantidade]]+E17-F17+BS17-AM17) -> 34 | AM17: =SUM('DEZEMBRO-25'!$H17:$AL17) -> 0 | BS17: =SUM(AN17:BR17) -> 0
A18: ATADURA DE ALGODÃO 10CM | B18: 0 | C18: 0 | D18: OLHAR COM ZE MARIA | G18: =SUM(Tabela1[[#This Row],[Quantidade]]+E18-F18+BS18-AM18) -> 0 | AM18: =SUM('DEZEMBRO-25'!$H18:$AL18) -> 0 | BS18: =SUM(AN18:BR18) -> 0
A19: ATADURA DE ALGODÃO 15CM | B19: 0 | C19: 0 | D19: OLHAR COM ZE MARIA | G19: =SUM(Tabela1[[#This Row],[Quantidade]]+E19-F19+BS19-AM19) -> 0 | AM19: =SUM('DEZEMBRO-25'!$H19:$AL19) -> 0 | BS19: =SUM(AN19:BR19) -> 0
A20: ATADURA DE ALGODÃO 20CM | B20: 0 | C20: 0 | D20: OLHAR COM ZE MARIA | G20: =SUM(Tabela1[[#This Row],[Quantidade]]+E20-F20+BS20-AM20) -> 0 | AM20: =SUM('DEZEMBRO-25'!$H20:$AL20) -> 0 | BS20: =SUM(AN20:BR20) -> 0
A21: BATERIA GLICOSE (GLICOSÍMETRO) | B21: 5 | C21: UND | D21: COMPRAR | G21: =SUM(Tabela1[[#This Row],[Quantidade]]+E21-F21+BS21-AM21) -> 5 | AM21: =SUM('DEZEMBRO-25'!$H21:$AL21) -> 0 | BS21: =SUM(AN21:BR21) -> 0
A22: BOLSA COLETORA DE URINA | B22: 0 | C22: UND | D22: COMPRA | G22: =SUM(Tabela1[[#This Row],[Quantidade]]+E22-F22+BS22-AM22) -> 0 | AM22: =SUM('DEZEMBRO-25'!$H22:$AL22) -> 0 | BS22: =SUM(AN22:BR22) -> 0
A23: BOM AR | B23: 5 | C23: UND | D23: COMPRAR | G23: =SUM(Tabela1[[#This Row],[Quantidade]]+E23-F23+BS23-AM23) -> 5 | AM23: =SUM('DEZEMBRO-25'!$H23:$AL23) -> 0 | BS23: =SUM(AN23:BR23) -> 0
A24: CADERNO BROCHURA CAP. DURA (grande) | B24: 90 | C24: UND | D24: MAIS 220 DE CAPA MOLE | G24: =SUM(Tabela1[[#This Row],[Quantidade]]+E24-F24+BS24-AM24) -> 90 | AM24: =SUM('DEZEMBRO-25'!$H24:$AL24) -> 0 | BS24: =SUM(AN24:BR24) -> 0
A25: CAIXA BOX | B25: 10 | C25: UND | D25: OLHAR COM RUAM | G25: =SUM(Tabela1[[#This Row],[Quantidade]]+E25-F25+BS25-AM25) -> 10 | AM25: =SUM('DEZEMBRO-25'!$H25:$AL25) -> 0 | BS25: =SUM(AN25:BR25) -> 0
A26: CANETA PARA RETROPROJETOR AZUL | B26: 0 | C26: 0 | D26: 0 | G26: =SUM(Tabela1[[#This Row],[Quantidade]]+E26-F26+BS26-AM26) -> 0 | AM26: =SUM('DEZEMBRO-25'!$H26:$AL26) -> 0 | BS26: =SUM(AN26:BR26) -> 0
A27: CANETA PARA RETROPROJETOR PRETA | B27: 0 | C27: 0 | D27: 0 | G27: =SUM(Tabela1[[#This Row],[Quantidade]]+E27-F27+BS27-AM27) -> 0 | AM27: =SUM('DEZEMBRO-25'!$H27:$AL27) -> 0 | BS27: =SUM(AN27:BR27) -> 0
A28: CANETA PARA RETROPROJETOR VERMELHO | B28: 0 | C28: 0 | D28: 0 | G28: =SUM(Tabela1[[#This Row],[Quantidade]]+E28-F28+BS28-AM28) -> 0 | AM28: =SUM('DEZEMBRO-25'!$H28:$AL28) -> 0 | BS28: =SUM(AN28:BR28) -> 0
A29: CATETER PERIFÉRICO 14G | B29: 6 | C29: CX | D29: C/100UN | G29: =SUM(Tabela1[[#This Row],[Quantidade]]+E29-F29+BS29-AM29) -> 6 | AM29: =SUM('DEZEMBRO-25'!$H29:$AL29) -> 0 | BS29: =SUM(AN29:BR29) -> 0
A30: CATETER PERIFÉRICO 20G | B30: 27 | C30: CX | D30: C/100UN | G30: =SUM(Tabela1[[#This Row],[Quantidade]]+E30-F30+BS30-AM30) -> 27 | AM30: =SUM('DEZEMBRO-25'!$H30:$AL30) -> 0 | BS30: =SUM(AN30:BR30) -> 0
A31: CATETER PERIFÉRICO 22G (PONTA AZUL) | B31: 49 | C31: CX | D31: C/100UN | G31: =SUM(Tabela1[[#This Row],[Quantidade]]+E31-F31+BS31-AM31) -> 49 | AM31: =SUM('DEZEMBRO-25'!$H31:$AL31) -> 0 | BS31: =SUM(AN31:BR31) -> 0
A32: CATETER PERIFÉRICO 24G | B32: 12 | C32: CX | D32: C/100UN | G32: =SUM(Tabela1[[#This Row],[Quantidade]]+E32-F32+BS32-AM32) -> 12 | AM32: =SUM('DEZEMBRO-25'!$H32:$AL32) -> 0 | BS32: =SUM(AN32:BR32) -> 0
A33: CLIPES N° 2 (p) | B33: 3 | C33: CX | D33: QUANTIDADES VARIADAS | G33: =SUM(Tabela1[[#This Row],[Quantidade]]+E33-F33+BS33-AM33) -> 3 | AM33: =SUM('DEZEMBRO-25'!$H33:$AL33) -> 0 | BS33: =SUM(AN33:BR33) -> 0
A34: CLIPES N° 6 (G) | B34: 7 | C34: CX | D34: QUANTIDADES VARIADAS | G34: =SUM(Tabela1[[#This Row],[Quantidade]]+E34-F34+BS34-AM34) -> 7 | AM34: =SUM('DEZEMBRO-25'!$H34:$AL34) -> 0 | BS34: =SUM(AN34:BR34) -> 0
A35: COADOR G | B35: 0 | C35: 0 | D35: 0 | G35: =SUM(Tabela1[[#This Row],[Quantidade]]+E35-F35+BS35-AM35) -> 0 | AM35: =SUM('DEZEMBRO-25'!$H35:$AL35) -> 0 | BS35: =SUM(AN35:BR35) -> 0
A36: COADOR M | B36: 0 | C36: 0 | D36: 0 | G36: =SUM(Tabela1[[#This Row],[Quantidade]]+E36-F36+BS36-AM36) -> 0 | AM36: =SUM('DEZEMBRO-25'!$H36:$AL36) -> 0 | BS36: =SUM(AN36:BR36) -> 0
A37: COLAR CERVICAL MÉDIO | B37: 0 | C37: 0 | D37: VER COM ZÉ MARIA | G37: =SUM(Tabela1[[#This Row],[Quantidade]]+E37-F37+BS37-AM37) -> 0 | AM37: =SUM('DEZEMBRO-25'!$H37:$AL37) -> 0 | BS37: =SUM(AN37:BR37) -> 0
A38: COMPRESSA DE GAZE (PCTO) | B38: TEM MUITO | C38: TEM MUITO | D38: TEM MUITO | G38: =SUM(Tabela1[[#This Row],[Quantidade]]+E38-F38+BS38-AM38) -> #VALUE! | AM38: =SUM('DEZEMBRO-25'!$H38:$AL38) -> 0 | BS38: =SUM(AN38:BR38) -> 0
A39: COMPRESSA DE GAZE 7.5x7.5cm (estéreo) | B39: 450 | C39: UND | D39: COMPRA | G39: =SUM(Tabela1[[#This Row],[Quantidade]]+E39-F39+BS39-AM39) -> 450 | AM39: =SUM('DEZEMBRO-25'!$H39:$AL39) -> 0 | BS39: =SUM(AN39:BR39) -> 0
A40: COPO DESCARTÁVEL | B40: TEM MUITO | C40: TEM MUITO | D40: TEM MUITO | G40: =SUM(Tabela1[[#This Row],[Quantidade]]+E40-F40+BS40-AM40) -> #VALUE! | AM40: =SUM('DEZEMBRO-25'!$H40:$AL40) -> 0 | BS40: =SUM(AN40:BR40) -> 0
...

Sheet 1-26
A1: ='DEZEMBRO-25'!A1 -> DATA DE INÍCIO: | B1: ='DEZEMBRO-25'!G1 -> ESTOQUE | C1: ='DEZEMBRO-25'!C1 -> DATA FINAL: | D1: ='DEZEMBRO-25'!D1 -> 45964 | E1: SOMA | F1: DE | G1: ESTOQUE | H1: 01/12/2025 | I1: 02/12/2025 | J1: 03/12/2025 | K1: 04/12/2025 | L1: 05/12/2025 | M1: 06/12/2025 | N1: 07/12/2025 | O1: 08/12/2025 | P1: 09/12/2025 | Q1: 10/12/2025 | R1: 11/12/2025 | S1: 12/12/2025 | T1: 13/12/2025 | U1: 14/12/2025 | V1: 15/12/2025 | W1: 16/12/2025 | X1: 17/12/2025 | Y1: 18/12/2025 | Z1: 19/12/2025 | AA1: 20/12/2025 | AB1: 21/12/2025 | AC1: 22/12/2025 | AD1: 23/12/2025 | AE1: 24/12/2025 | AF1: 25/12/2025 | AG1: 26/12/2025 | AH1: 27/12/2025 | AI1: 28/12/2025 | AJ1: 29/12/2025 | AK1: 30/12/2025 | AL1: 31/12/2025 | AM1: SAIDA | AN1: 01/12/2025 | AO1: 02/12/2025 | AP1: 03/12/2025 | AQ1: 04/12/2025 | AR1: 05/12/2025 | AS1: 06/12/2025 | AT1: 07/12/2025 | AU1: 08/12/2025 | AV1: 09/12/2025 | AW1: 10/12/2025 | AX1: 11/12/2025 | AY1: 12/12/2025 | AZ1: 13/12/2025 | BA1: 14/12/2025 | BB1: 15/12/2025 | BC1: 16/12/2025 | BD1: 17/12/2025 | BE1: 18/12/2025 | BF1: 19/12/2025 | BG1: 20/12/2025 | BH1: 21/12/2025 | BI1: 22/12/2025 | BJ1: 23/12/2025 | BK1: 24/12/2025 | BL1: 25/12/2025 | BM1: 26/12/2025 | BN1: 27/12/2025 | BO1: 28/12/2025 | BP1: 29/12/2025 | BQ1: 30/12/2025 | BR1: 31/12/2025 | BS1: ENTRADA
A2: ='DEZEMBRO-25'!A2 -> Produto | B2: ='DEZEMBRO-25'!G2 -> SUBTOTAL | C2: ='DEZEMBRO-25'!C2 -> CLAS. | D2: ='DEZEMBRO-25'!D2 -> Observação | E2: ENTRADA | F2: SAÍDA | G2: SUBTOTAL
A3: ='DEZEMBRO-25'!A3 -> ÁGUA SANITÁRIA 2L | B3: ='DEZEMBRO-25'!G3 -> 64 | C3: ='DEZEMBRO-25'!C3 -> CX | D3: ='DEZEMBRO-25'!D3 -> C/100UN | G3: =#REF!+E3-F3-AM3+BS3 -> #REF! | AM3: =SUM(H3:AL3) -> 0 | BS3: =SUM(AN3:BR3) -> 0
A4: ='DEZEMBRO-25'!A4 -> AGULHA HIPODÉRMICA 13X4.5 C/100 | B4: ='DEZEMBRO-25'!G4 -> 60 | C4: ='DEZEMBRO-25'!C4 -> CX | D4: ='DEZEMBRO-25'!D4 -> C/100UN | G4: =#REF!+E4-F4-AM4 -> #REF! | AM4: =SUM(H4:AL4) -> 0 | BS4: =SUM(AN4:BR4) -> 0
A5: ='DEZEMBRO-25'!A5 -> AGULHA HIPODÉRMICA 20X5.5 C/100 | B5: ='DEZEMBRO-25'!G5 -> 60 | C5: ='DEZEMBRO-25'!C5 -> CX | D5: ='DEZEMBRO-25'!D5 -> C/100UN | G5: =#REF!+E5-F5-AM5 -> #REF! | AM5: =SUM(H5:AL5) -> 0 | BS5: =SUM(AN5:BR5) -> 0
A6: ='DEZEMBRO-25'!A6 -> AGULHA HIPODÉRMICA 25X8 C/100 | B6: ='DEZEMBRO-25'!G6 -> 71 | C6: ='DEZEMBRO-25'!C6 -> CX | D6: ='DEZEMBRO-25'!D6 -> C/100UN | G6: =#REF!+E6-F6-AM6 -> #REF! | AM6: =SUM(H6:AL6) -> 0 | BS6: =SUM(AN6:BR6) -> 0
A7: ='DEZEMBRO-25'!A7 -> AGULHA HIPODÉRMICA 40X12 C/100 | B7: ='DEZEMBRO-25'!G7 -> 20 | C7: ='DEZEMBRO-25'!C7 -> CX | D7: ='DEZEMBRO-25'!D7 -> C/100UN | G7: =#REF!+E7-F7-AM7 -> #REF! | AM7: =SUM(H7:AL7) -> 0 | BS7: =SUM(AN7:BR7) -> 0
A8: ='DEZEMBRO-25'!A8 -> ÁLCOOL | B8: ='DEZEMBRO-25'!G8 -> #VALUE! | C8: ='DEZEMBRO-25'!C8 -> TEM MUITO | D8: ='DEZEMBRO-25'!D8 -> TEM MUITO | G8: =#REF!+E8-F8-AM8 -> #REF! | AM8: =SUM(H8:AL8) -> 0 | BS8: =SUM(AN8:BR8) -> 0
A9: ='DEZEMBRO-25'!A9 -> ALGODÃO HIDRÓFILO | B9: ='DEZEMBRO-25'!G9 -> 125 | C9: ='DEZEMBRO-25'!C9 -> UND | D9: ='DEZEMBRO-25'!D9 -> 500G | G9: =#REF!+E9-F9-AM9 -> #REF! | AM9: =SUM(H9:AL9) -> 0 | BS9: =SUM(AN9:BR9) -> 0
A10: ='DEZEMBRO-25'!A10 -> ALGODÃO ORTOPÉDICO 10CM | B10: ='DEZEMBRO-25'!G10 -> 0 | C10: ='DEZEMBRO-25'!C10 -> 0 | D10: ='DEZEMBRO-25'!D10 -> 0 | G10: =#REF!+E10-F10-AM10 -> #REF! | AM10: =SUM(H10:AL10) -> 0 | BS10: =SUM(AN10:BR10) -> 0
A11: ='DEZEMBRO-25'!A11 -> ALGODÃO ORTOPÉDICO 20CM | B11: ='DEZEMBRO-25'!G11 -> 100 | C11: ='DEZEMBRO-25'!C11 -> UND | D11: ='DEZEMBRO-25'!D11 -> OLHAR COM ZE MARIA | G11: =#REF!+E11-F11-AM11 -> #REF! | AM11: =SUM(H11:AL11) -> 0 | BS11: =SUM(AN11:BR11) -> 0
A12: ='DEZEMBRO-25'!A12 -> ALMOTOLIA 250 ML | B12: ='DEZEMBRO-25'!G12 -> 100 | C12: ='DEZEMBRO-25'!C12 -> UND | D12: ='DEZEMBRO-25'!D12 -> NÃO SAI | G12: =#REF!+E12-F12-AM12 -> #REF! | AM12: =SUM(H12:AL12) -> 0 | BS12: =SUM(AN12:BR12) -> 0
A13: ='DEZEMBRO-25'!A13 -> ALMOTOLIA 500 ML | B13: ='DEZEMBRO-25'!G13 -> 0 | C13: ='DEZEMBRO-25'!C13 -> 0 | D13: ='DEZEMBRO-25'!D13 -> 0 | G13: =#REF!+E13-F13-AM13 -> #REF! | AM13: =SUM(H13:AL13) -> 0 | BS13: =SUM(AN13:BR13) -> 0
A14: ='DEZEMBRO-25'!A14 -> APARELHO MEDIDOR GLICOSE (GLICOSÍMETRO) | B14: ='DEZEMBRO-25'!G14 -> #VALUE! | C14: ='DEZEMBRO-25'!C14 -> CONTAR | D14: ='DEZEMBRO-25'!D14 -> CONTAR | G14: =#REF!+E14-F14-AM14 -> #REF! | AM14: =SUM(H14:AL14) -> 0 | BS14: =SUM(AN14:BR14) -> 0
A15: ='DEZEMBRO-25'!A15 -> ATADURA CREPE 10CM | B15: ='DEZEMBRO-25'!G15 -> 90 | C15: ='DEZEMBRO-25'!C15 -> PCT | D15: ='DEZEMBRO-25'!D15 -> SAI MUITO | G15: =#REF!+E15-F15-AM15 -> #REF! | AM15: =SUM(H15:AL15) -> 0 | BS15: =SUM(AN15:BR15) -> 0
... A80: ='DEZEMBRO-25'!A80 -> PÁ DE LIXO | B80: ='DEZEMBRO-25'!G80 -> 0 | C80: ='DEZEMBRO-25'!C80 -> 0 | D80: ='DEZEMBRO-25'!D80 -> 0 | G80: =#REF!+E80-F80-AM80 -> #REF! | AM80: =SUM(H80:AL80) -> 0 | BS80: =SUM(AN80:BR80) -> 0
A81: ='DEZEMBRO-25'!A81 -> PANO DE PRATO | B81: ='DEZEMBRO-25'!G81 -> 0 | D81: ='DEZEMBRO-25'!D81 -> COMPRAS | G81: =#REF!+E81-F81-AM81 -> #REF! | AM81: =SUM(H81:AL81) -> 0 | BS81: =SUM(AN81:BR81) -> 0
A82: ='DEZEMBRO-25'!A82 -> PILHA AAA (COMUN) | B82: ='DEZEMBRO-25'!G82 -> 0 | C82: O | D82: ='DEZEMBRO-25'!D82 -> O | G82: =#REF!+E82-F82-AM82 -> #REF! | AM82: =SUM(H82:AL82) -> 0 | BS82: =SUM(AN82:BR82) -> 0
A83: ='DEZEMBRO-25'!A83 -> PILHA AAA (PALITO) | B83: ='DEZEMBRO-25'!G83 -> 0 | C83: O | D83: ='DEZEMBRO-25'!D83 -> O | G83: =#REF!+E83-F83-AM83 -> #REF! | AM83: =SUM(H83:AL83) -> 0 | BS83: =SUM(AN83:BR83) -> 0
A84: ='DEZEMBRO-25'!A84 -> PISTOLA COLA QUENTE GRANDE | B84: ='DEZEMBRO-25'!G84 -> 0 | C84: O | D84: ='DEZEMBRO-25'!D84 -> O | G84: =#REF!+E84-F84-AM84 -> #REF! | AM84: =SUM(H84:AL84) -> 0 | BS84: =SUM(AN84:BR84) -> 0
A85: ='DEZEMBRO-25'!A85 -> PORTA CANETA | B85: ='DEZEMBRO-25'!G85 -> 0 | C85: O | D85: ='DEZEMBRO-25'!D85 -> O | G85: =#REF!+E85-F85-AM85 -> #REF! | AM85: =SUM(H85:AL85) -> 0 | BS85: =SUM(AN85:BR85) -> 0
A86: ='DEZEMBRO-25'!A86 -> PRANCHETA | B86: ='DEZEMBRO-25'!G86 -> 0 | C86: O | D86: ='DEZEMBRO-25'!D86 -> O | G86: =#REF!+E86-F86-AM86 -> #REF! | AM86: =SUM(H86:AL86) -> 0 | BS86: =SUM(AN86:BR86) -> 0
A87: ='DEZEMBRO-25'!A87 -> PURIFICADOR | B87: ='DEZEMBRO-25'!G87 -> 0 | C87: O | D87: ='DEZEMBRO-25'!D87 -> O | G87: =#REF!+E87-F87-AM87 -> #REF! | AM87: =SUM(H87:AL87) -> 0 | BS87: =SUM(AN87:BR87) -> 0
A88: ='DEZEMBRO-25'!A88 -> REGUA 30 CM | B88: ='DEZEMBRO-25'!G88 -> #VALUE! | C88: TEM MUITO | D88: ='DEZEMBRO-25'!D88 -> TEM MUITO | G88: =#REF!+E88-F88-AM88 -> #REF! | AM88: =SUM(H88:AL88) -> 0 | BS88: =SUM(AN88:BR88) -> 0
A89: ='DEZEMBRO-25'!A89 -> SABÃO LÍQUIDO | B89: ='DEZEMBRO-25'!G89 -> 51 | C89: UND | D89: ='DEZEMBRO-25'!D89 -> SAIDA REGULAR | G89: =#REF!+E89-F89-AM89 -> #REF! | AM89: =SUM(H89:AL89) -> 0 | BS89: =SUM(AN89:BR89) -> 0
A90: ='DEZEMBRO-25'!A90 -> SACO DE LIXO 100lt | B90: ='DEZEMBRO-25'!G90 -> 70 | C90: PCT | D90: ='DEZEMBRO-25'!D90 -> SAI MUITO | G90: =#REF!+E90-F90-AM90 -> #REF! | AM90: =SUM(H90:AL90) -> 0 | BS90: =SUM(AN90:BR90) -> 0
A91: ='DEZEMBRO-25'!A91 -> SCALP 23G | B91: ='DEZEMBRO-25'!G91 -> 33 | C91: CX | D91: ='DEZEMBRO-25'!D91 -> NÃO SAI | G91: =#REF!+E91-F91-AM91 -> #REF! | AM91: =SUM(H91:AL91) -> 0 | BS91: =SUM(AN91:BR91) -> 0
A92: ='DEZEMBRO-25'!A92 -> SERINGA HIPODÉRMICA 20ML | B92: ='DEZEMBRO-25'!G92 -> 0 | C92: 0 | D92: ='DEZEMBRO-25'!D92 -> 0 | G92: =#REF!+E92-F92-AM92 -> #REF! | AM92: =SUM(H92:AL92) -> 0 | BS92: =SUM(AN92:BR92) -> 0
A93: ='DEZEMBRO-25'!A93 -> SERINGA HIPODÉRMICA 3ML | B93: ='DEZEMBRO-25'!G93 -> #VALUE! | C93: TEM MUITO | D93: ='DEZEMBRO-25'!D93 -> TEM MUITO | G93: =#REF!+E93-F93-AM93 -> #REF! | AM93: =SUM(H93:AL93) -> 0 | BS93: =SUM(AN93:BR93) -> 0
A94: ='DEZEMBRO-25'!A94 -> SERINGA P/INSULINA 1ML | B94: ='DEZEMBRO-25'!G94 -> #VALUE! | C94: FICAR DE OLHO | D94: ='DEZEMBRO-25'!D94 -> FICAR DE OLHO | G94: =#REF!+E94-F94-AM94 -> #REF! | AM94: =SUM(H94:AL94) -> 0 | BS94: =SUM(AN94:BR94) -> 0
A95: ='DEZEMBRO-25'!A95 -> SONDA DE FOLEY 14 | B95: ='DEZEMBRO-25'!G95 -> #VALUE! | C95: NÃO SAI | D95: ='DEZEMBRO-25'!D95 -> NÃO SAI | G95: =#REF!+E95-F95-AM95 -> #REF! | AM95: =SUM(H95:AL95) -> 0 | BS95: =SUM(AN95:BR95) -> 0
A96: ='DEZEMBRO-25'!A96 -> SONDA URETRAL N°10 | B96: ='DEZEMBRO-25'!G96 -> 50 | C96: UND | D96: ='DEZEMBRO-25'!D96 -> NÃO SAI | G96: =#REF!+E96-F96-AM96 -> #REF! | AM96: =SUM(H96:AL96) -> 0 | BS96: =SUM(AN96:BR96) -> 0
A97: ='DEZEMBRO-25'!A97 -> SONDA URETRAL N°12 | B97: ='DEZEMBRO-25'!G97 -> #VALUE! | C97: UND | D97: ='DEZEMBRO-25'!D97 -> SAI MUITO | G97: =#REF!+E97-F97-AM97 -> #REF! | AM97: =SUM(H97:AL97) -> 0 | BS97: =SUM(AN97:BR97) -> 0
A98: ='DEZEMBRO-25'!A98 -> SONDA URETRAL N°14 | B98: ='DEZEMBRO-25'!G98 -> 0 | C98: 0 | D98: ='DEZEMBRO-25'!D98 -> OLHAR COM ZE MARIA | G98: =#REF!+E98-F98-AM98 -> #REF! | AM98: =SUM(H98:AL98) -> 0 | BS98: =SUM(AN98:BR98) -> 0
A99: ='DEZEMBRO-25'!A99 -> SONDA URETRAL N°14 TRANSF. MARROM GÁS ETO | B99: ='DEZEMBRO-25'!G99 -> 100 | C99: UND | D99: ='DEZEMBRO-25'!D99 -> OLHAR COM ZE MARIA | G99: =#REF!+E99-F99-AM99 -> #REF! | AM99: =SUM(H99:AL99) -> 0 | BS99: =SUM(AN99:BR99) -> 0
A100: ='DEZEMBRO-25'!A100 -> SORO 100 ML | B100: ='DEZEMBRO-25'!G100 -> 1860 | C100: UND | D100: ='DEZEMBRO-25'!D100 -> SAIDA REGULAR | G100: =#REF!+E100-F100-AM100 -> #REF! | AM100: =SUM(H100:AL100) -> 0 | BS100: =SUM(AN100:BR100) -> 0
A101: ='DEZEMBRO-25'!A101 -> SORO 500 ML | B101: ='DEZEMBRO-25'!G101 -> 3 | C101: CX | D101: ='DEZEMBRO-25'!D101 -> PAM | G101: =#REF!+E101-F101-AM101 -> #REF! | AM101: =SUM(H101:AL101) -> 0 | BS101: =SUM(AN101:BR101) -> 0
A102: ='DEZEMBRO-25'!A102 -> SORO GLICOSADO 250 ML | B102: ='DEZEMBRO-25'!G102 -> 336 | C102: UND | D102: ='DEZEMBRO-25'!D102 -> SAIDA EXPECIFICA | G102: =#REF!+E102-F102-AM102 -> #REF! | AM102: =SUM(H102:AL102) -> 0 | BS102: =SUM(AN102:BR102) -> 0
A103: ='DEZEMBRO-25'!A103 -> SORO GLICOSADO 500 ML | B103: ='DEZEMBRO-25'!G103 -> 0 | C103: 0 | D103: ='DEZEMBRO-25'!D103 -> 0 | G103: =#REF!+E103-F103-AM103 -> #REF! | AM103: =SUM(H103:AL103) -> 0 | BS103: =SUM(AN103:BR103) -> 0
A104: ='DEZEMBRO-25'!A104 -> TALA ARAMADA KIT | B104: ='DEZEMBRO-25'!G104 -> 0 | C104: 0 | D104: ='DEZEMBRO-25'!D104 -> 0 | G104: =#REF!+E104-F104-AM104 -> #REF! | AM104: =SUM(H104:AL104) -> 0 | BS104: =SUM(AN104:BR104) -> 0
...

Sheet 2-26

Sheet 3-26

Sheet 4-26

Sheet 5-26

Sheet 6-26

Sheet 7-26

Sheet 8-26

Sheet 9-26

Sheet 10-26

Sheet 11-26

Sheet 12-26
